Workbook
Name Slicer_Channel: #N/A
Name Slicer_Product_Category: #N/A
Name Slicer_Region: #N/A

Sheet Raw_Data
A1: Order_ID | B1: Order_Date | C1: Customer_ID | D1: Customer_Age | E1: Customer_Gender | F1: Region | G1: State | H1: City | I1: Product_Category | J1: Quantity | K1: Unit_Price | L1: Total_Amount | M1: Channel
A2: ORD-100001 | B2: 44790 | C2: CUST-1409 | D2: 65 | E2: Male | F2: Midwest | G2: Illinois | H2: Naperville | I2: Electronics | J2: 2 | K2: 374.77 | L2: 749.54 | M2: Online
A3: ORD-100002 | B3: 44753 | C3: CUST-4582 | D3: 32 | E3: Female | F3: Northeast | G3: Pennsylvania | H3: Philadelphia | I3: Sports | J3: 7 | K3: 70.7 | L3: 494.9 | M3: Online
A4: ORD-100003 | B4: 44575 | C4: CUST-3615 | D4: 62 | E4: Male | F4: South | G4: Texas | H4: Houston | I4: Home | J4: 2 | K4: 45.97 | L4: 91.94 | M4: Online
A5: ORD-100004 | B5: 45266 | C5: CUST-5333 | D5: 69 | E5: Male | F5: West | G5: Colorado | H5: Denver | I5: Beauty | J5: 2 | K5: 70.72 | L5: 141.44 | M5: In-Store
A6: ORD-100005 | B6: 45302 | C6: CUST-4150 | D6: 63 | E6: Male | F6: Midwest | G6: Ohio | H6: Columbus | I6: Clothing | J6: 2 | K6: 66.32 | L6: 132.64 | M6: Online
A7: ORD-100006 | B7: 45309 | C7: CUST-3664 | D7: 41 | E7: Male | F7: South | G7: Georgia | H7: Athens | I7: Electronics | J7: 3 | K7: 343.78 | L7: 1031.34 | M7: Online
A8: ORD-100007 | B8: 45508 | C8: CUST-7216 | D8: 35 | E8: Other | F8: Midwest | G8: Michigan | H8: Grand Rapids | I8: Electronics | J8: 4 | K8: 501.99 | L8: 2007.96 | M8: In-Store
A9: ORD-100008 | B9: 45383 | C9: CUST-5386 | D9: 22 | E9: Male | F9: South | G9: Texas | H9: Austin | I9: Beauty | J9: 7 | K9: 107.32 | L9: 751.24 | M9: In-Store
A10: ORD-100009 | B10: 44854 | C10: CUST-5339 | D10: 26 | E10: Male | F10: South | G10: Georgia | H10: Athens | I10: Beauty | J10: 7 | K10: 49.82 | L10: 348.74 | M10: In-Store
A11: ORD-100010 | B11: 44845 | C11: CUST-9348 | D11: 49 | E11: Male | F11: Northeast | G11: New York | H11: New York | I11: Clothing | J11: 7 | K11: 95.52 | L11: 668.64 | M11: Online
A12: ORD-100011 | B12: 45520 | C12: CUST-9669 | D12: 34 | E12: Other | F12: Northeast | G12: Pennsylvania | H12: Allentown | I12: Electronics | J12: 5 | K12: 472.73 | L12: 2363.65 | M12: Online
A13: ORD-100012 | B13: 45163 | C13: CUST-8123 | D13: 28 | E13: Male | F13: South | G13: Georgia | H13: Atlanta | I13: Sports | J13: 2 | K13: 220.22 | L13: 440.44 | M13: Online
... A5001: ORD-105000 | B5001: 45518 | C5001: CUST-9617 | D5001: 53 | E5001: Female | F5001: South | G5001: Florida | H5001: Tampa | I5001: Beauty | J5001: 6 | K5001: 61.18 | L5001: 367.08 | M5001: Online

Sheet Cleaned_Data
A1: Order_ID | B1: Order_Date | C1: Customer_ID | D1: Age | E1: Gender | F1: Region | G1: State | H1: City | I1: Product_Category | J1: Quantity | K1: Unit_Price | L1: Total_Amount | M1: Channel | N1: Age_Group
A2: ORD-100001 | B2: 44790 | C2: CUST-1409 | D2: 65 | E2: Male | F2: Midwest | G2: Illinois | H2: Naperville | I2: Electronics | J2: 2 | K2: 374.77 | L2: 749.54 | M2: Online | N2: =IF(D2<25,"18-24", IF(D2<35,"25-34", IF(D2<45,"35-44", IF(D2<55,"45-54","55+")))) -> 55+
A3: ORD-100002 | B3: 44753 | C3: CUST-4582 | D3: 32 | E3: Female | F3: Northeast | G3: Pennsylvania | H3: Philadelphia | I3: Sports | J3: 7 | K3: 70.7 | L3: 494.9 | M3: Online | N3: =IF(D3<25,"18-24", IF(D3<35,"25-34", IF(D3<45,"35-44", IF(D3<55,"45-54","55+")))) -> 25-34
A4: ORD-100003 | B4: 44575 | C4: CUST-3615 | D4: 62 | E4: Male | F4: South | G4: Texas | H4: Houston | I4: Home | J4: 2 | K4: 45.97 | L4: 91.94 | M4: Online | N4: =IF(D4<25,"18-24", IF(D4<35,"25-34", IF(D4<45,"35-44", IF(D4<55,"45-54","55+")))) -> 55+
A5: ORD-100004 | B5: 45266 | C5: CUST-5333 | D5: 69 | E5: Male | F5: West | G5: Colorado | H5: Denver | I5: Beauty | J5: 2 | K5: 70.72 | L5: 141.44 | M5: In-Store | N5: =IF(D5<25,"18-24", IF(D5<35,"25-34", IF(D5<45,"35-44", IF(D5<55,"45-54","55+")))) -> 55+
A6: ORD-100005 | B6: 45302 | C6: CUST-4150 | D6: 63 | E6: Male | F6: Midwest | G6: Ohio | H6: Columbus | I6: Clothing | J6: 2 | K6: 66.32 | L6: 132.64 | M6: Online | N6: =IF(D6<25,"18-24", IF(D6<35,"25-34", IF(D6<45,"35-44", IF(D6<55,"45-54","55+")))) -> 55+
A7: ORD-100006 | B7: 45309 | C7: CUST-3664 | D7: 41 | E7: Male | F7: South | G7: Georgia | H7: Athens | I7: Electronics | J7: 3 | K7: 343.78 | L7: 1031.34 | M7: Online | N7: =IF(D7<25,"18-24", IF(D7<35,"25-34", IF(D7<45,"35-44", IF(D7<55,"45-54","55+")))) -> 35-44
A8: ORD-100007 | B8: 45508 | C8: CUST-7216 | D8: 35 | E8: Other | F8: Midwest | G8: Michigan | H8: Grand Rapids | I8: Electronics | J8: 4 | K8: 501.99 | L8: 2007.96 | M8: In-Store | N8: =IF(D8<25,"18-24", IF(D8<35,"25-34", IF(D8<45,"35-44", IF(D8<55,"45-54","55+")))) -> 35-44
A9: ORD-100008 | B9: 45383 | C9: CUST-5386 | D9: 22 | E9: Male | F9: South | G9: Texas | H9: Austin | I9: Beauty | J9: 7 | K9: 107.32 | L9: 751.24 | M9: In-Store | N9: =IF(D9<25,"18-24", IF(D9<35,"25-34", IF(D9<45,"35-44", IF(D9<55,"45-54","55+")))) -> 18-24
A10: ORD-100009 | B10: 44854 | C10: CUST-5339 | D10: 26 | E10: Male | F10: South | G10: Georgia | H10: Athens | I10: Beauty | J10: 7 | K10: 49.82 | L10: 348.74 | M10: In-Store | N10: =IF(D10<25,"18-24", IF(D10<35,"25-34", IF(D10<45,"35-44", IF(D10<55,"45-54","55+")))) -> 25-34
A11: ORD-100010 | B11: 44845 | C11: CUST-9348 | D11: 49 | E11: Male | F11: Northeast | G11: New York | H11: New York | I11: Clothing | J11: 7 | K11: 95.52 | L11: 668.64 | M11: Online | N11: =IF(D11<25,"18-24", IF(D11<35,"25-34", IF(D11<45,"35-44", IF(D11<55,"45-54","55+")))) -> 45-54
A12: ORD-100011 | B12: 45520 | C12: CUST-9669 | D12: 34 | E12: Other | F12: Northeast | G12: Pennsylvania | H12: Allentown | I12: Electronics | J12: 5 | K12: 472.73 | L12: 2363.65 | M12: Online | N12: =IF(D12<25,"18-24", IF(D12<35,"25-34", IF(D12<45,"35-44", IF(D12<55,"45-54","55+")))) -> 25-34
A13: ORD-100012 | B13: 45163 | C13: CUST-8123 | D13: 28 | E13: Male | F13: South | G13: Georgia | H13: Atlanta | I13: Sports | J13: 2 | K13: 220.22 | L13: 440.44 | M13: Online | N13: =IF(D13<25,"18-24", IF(D13<35,"25-34", IF(D13<45,"35-44", IF(D13<55,"45-54","55+")))) -> 25-34
... A5001: ORD-105000 | B5001: 45518 | C5001: CUST-9617 | D5001: 53 | E5001: Female | F5001: South | G5001: Florida | H5001: Tampa | I5001: Beauty | J5001: 6 | K5001: 61.18 | L5001: 367.08 | M5001: Online | N5001: =IF(D5001<25,"18-24", IF(D5001<35,"25-34", IF(D5001<45,"35-44", IF(D5001<55,"45-54","55+")))) -> 45-54

Sheet KPIs
A1: Total Sales | B1: Total Transactions | C1: Average Order Value (AOV) | D1: Total Units Sold (Quantity) | E1: Average Customer Age
A2: =SUM(Cleaned_Data!L2:L5001) -> 3441717.7 | B2: =COUNTA(Cleaned_Data!A2:A5001) -> 5000 | C2: =SUM(Cleaned_Data!L2:L5001) / COUNTA(Cleaned_Data!A2:A5001) -> 688.34353 | D2: =SUM(Cleaned_Data!J2:J5001) -> 22631 | E2: =AVERAGE(Cleaned_Data!D2:D5001) -> 46.7034

Sheet Pivot_Tables
A1: Sales Over Time (Pivot) | D1: SalesOverTime_Chart
A2: Row Labels | B2: Sum of Total_Amount
A3: 2022 | B3: 1150430.1
A4: Jan | B4: 94418.92
A5: Feb | B5: 82319.17
A6: Mar | B6: 104542.52
A7: Apr | B7: 112619.82
A8: May | B8: 81896.85
A9: Jun | B9: 93525.94
A10: Jul | B10: 92348.56
A11: Aug | B11: 101814.52
A12: Sep | B12: 97020.65
A13: Oct | B13: 112966.09
A14: Nov | B14: 102858.75
... A35: Jun | B35: 99452.06
A36: Jul | B36: 87752.61 | D36: SalesByCategory_Chart
A37: Aug | B37: 90953.25
A38: Sep | B38: 87252.36
A39: Oct | B39: 130835.28
A40: Nov | B40: 78558.13
A41: Dec | B41: 95335.78
A44: Sales by Product Category (Pivot)
A45: Row Labels | B45: Sum of Total_Amount
A46: Beauty | B46: 282724.56
A47: Clothing | B47: 383195.72
A48: Sports | B48: 604014.92
A49: Home | B49: 714713.6
A50: Electronics | B50: 1457068.9
A54: Sales by State (Pivot)
A55: Row Labels | B55: Sum of Total_Amount | D55: Sales by State
A56: Pennsylvania | B56: 255643.28
A57: Illinois | B57: 265182.1
A58: New York | B58: 267617.36
A59: Colorado | B59: 277685.23
A60: California | B60: 278692.66
A61: Georgia | B61: 285990.85
A62: Washington | B62: 291187.4
A63: Florida | B63: 293961.96
A64: Michigan | B64: 295286.86
A65: Ohio | B65: 302529.93
...

Sheet Dashboard
A1: Total Sales $3,441,717.66 | E1: Total Transactions 5000 | I1: Average Order Value (AOV) $688.34 | M1: Total Units Sold 22631 | Q1: Average Customer Age 47
